2021-04-04 22:06:01,031 ERROR:         Exception on /user/Andrei1 [GET] [in /Users/inwaves/anaconda3/envs/todo-backend/lib/python3.8/site-packages/flask/app.py:1891]
Traceback (most recent call last):
  File "/Users/inwaves/anaconda3/envs/todo-backend/lib/python3.8/site-packages/flask/app.py", line 2447, in wsgi_app
    response = self.full_dispatch_request()
  File "/Users/inwaves/anaconda3/envs/todo-backend/lib/python3.8/site-packages/flask/app.py", line 1952, in full_dispatch_request
    rv = self.handle_user_exception(e)
  File "/Users/inwaves/anaconda3/envs/todo-backend/lib/python3.8/site-packages/flask/app.py", line 1821, in handle_user_exception
    reraise(exc_type, exc_value, tb)
  File "/Users/inwaves/anaconda3/envs/todo-backend/lib/python3.8/site-packages/flask/_compat.py", line 39, in reraise
    raise value
  File "/Users/inwaves/anaconda3/envs/todo-backend/lib/python3.8/site-packages/flask/app.py", line 1950, in full_dispatch_request
    rv = self.dispatch_request()
  File "/Users/inwaves/anaconda3/envs/todo-backend/lib/python3.8/site-packages/flask/app.py", line 1936, in dispatch_request
    return self.view_functions[rule.endpoint](**req.view_args)
  File "/Users/inwaves/anaconda3/envs/todo-backend/lib/python3.8/site-packages/flask_login/utils.py", line 272, in decorated_view
    return func(*args, **kwargs)
  File "/Users/inwaves/inwaves-repository/microblog/app/routes.py", line 129, in user
    return render_template("user.html",
  File "/Users/inwaves/anaconda3/envs/todo-backend/lib/python3.8/site-packages/flask/templating.py", line 138, in render_template
    ctx.app.jinja_env.get_or_select_template(template_name_or_list),
  File "/Users/inwaves/anaconda3/envs/todo-backend/lib/python3.8/site-packages/jinja2/environment.py", line 930, in get_or_select_template
    return self.get_template(template_name_or_list, parent, globals)
  File "/Users/inwaves/anaconda3/envs/todo-backend/lib/python3.8/site-packages/jinja2/environment.py", line 883, in get_template
    return self._load_template(name, self.make_globals(globals))
  File "/Users/inwaves/anaconda3/envs/todo-backend/lib/python3.8/site-packages/jinja2/environment.py", line 857, in _load_template
    template = self.loader.load(self, name, globals)
  File "/Users/inwaves/anaconda3/envs/todo-backend/lib/python3.8/site-packages/jinja2/loaders.py", line 127, in load
    code = environment.compile(source, name, filename)
  File "/Users/inwaves/anaconda3/envs/todo-backend/lib/python3.8/site-packages/jinja2/environment.py", line 638, in compile
    self.handle_exception(source=source_hint)
  File "/Users/inwaves/anaconda3/envs/todo-backend/lib/python3.8/site-packages/jinja2/environment.py", line 832, in handle_exception
    reraise(*rewrite_traceback_stack(source=source))
  File "/Users/inwaves/anaconda3/envs/todo-backend/lib/python3.8/site-packages/jinja2/_compat.py", line 28, in reraise
    raise value.with_traceback(tb)
  File "/Users/inwaves/inwaves-repository/microblog/app/templates/user.html", line 46, in template
    {% endif %}
jinja2.exceptions.TemplateSyntaxError: Encountered unknown tag 'endif'. Jinja was looking for the following tags: 'endblock'. The innermost block that needs to be closed is 'block'.
2021-04-04 22:06:37,824 INFO:         Microblog starting up [in /Users/inwaves/inwaves-repository/microblog/app/__init__.py:58]
2021-04-04 22:13:28,765 INFO:         Microblog starting up [in /Users/inwaves/inwaves-repository/microblog/app/__init__.py:58]
2021-04-04 22:34:02,266 INFO:         Microblog starting up [in /Users/inwaves/inwaves-repository/microblog/app/__init__.py:58]
2021-04-04 22:34:10,051 ERROR:         Exception on /reset_password_request [POST] [in /Users/inwaves/anaconda3/envs/todo-backend/lib/python3.8/site-packages/flask/app.py:1891]
Traceback (most recent call last):
  File "/Users/inwaves/anaconda3/envs/todo-backend/lib/python3.8/site-packages/flask/app.py", line 2447, in wsgi_app
    response = self.full_dispatch_request()
  File "/Users/inwaves/anaconda3/envs/todo-backend/lib/python3.8/site-packages/flask/app.py", line 1952, in full_dispatch_request
    rv = self.handle_user_exception(e)
  File "/Users/inwaves/anaconda3/envs/todo-backend/lib/python3.8/site-packages/flask/app.py", line 1821, in handle_user_exception
    reraise(exc_type, exc_value, tb)
  File "/Users/inwaves/anaconda3/envs/todo-backend/lib/python3.8/site-packages/flask/_compat.py", line 39, in reraise
    raise value
  File "/Users/inwaves/anaconda3/envs/todo-backend/lib/python3.8/site-packages/flask/app.py", line 1950, in full_dispatch_request
    rv = self.dispatch_request()
  File "/Users/inwaves/anaconda3/envs/todo-backend/lib/python3.8/site-packages/flask/app.py", line 1936, in dispatch_request
    return self.view_functions[rule.endpoint](**req.view_args)
  File "/Users/inwaves/inwaves-repository/microblog/app/routes.py", line 208, in reset_password_request
    send_password_reset_email(user)
  File "/Users/inwaves/inwaves-repository/microblog/app/mail_framework.py", line 28, in send_password_reset_email
    html_body=render_template("email/app/templates/reset_password.html", user=user, token=token),
  File "/Users/inwaves/anaconda3/envs/todo-backend/lib/python3.8/site-packages/flask/templating.py", line 138, in render_template
    ctx.app.jinja_env.get_or_select_template(template_name_or_list),
  File "/Users/inwaves/anaconda3/envs/todo-backend/lib/python3.8/site-packages/jinja2/environment.py", line 930, in get_or_select_template
    return self.get_template(template_name_or_list, parent, globals)
  File "/Users/inwaves/anaconda3/envs/todo-backend/lib/python3.8/site-packages/jinja2/environment.py", line 883, in get_template
    return self._load_template(name, self.make_globals(globals))
  File "/Users/inwaves/anaconda3/envs/todo-backend/lib/python3.8/site-packages/jinja2/environment.py", line 857, in _load_template
    template = self.loader.load(self, name, globals)
  File "/Users/inwaves/anaconda3/envs/todo-backend/lib/python3.8/site-packages/jinja2/loaders.py", line 115, in load
    source, filename, uptodate = self.get_source(environment, name)
  File "/Users/inwaves/anaconda3/envs/todo-backend/lib/python3.8/site-packages/flask/templating.py", line 60, in get_source
    return self._get_source_fast(environment, template)
  File "/Users/inwaves/anaconda3/envs/todo-backend/lib/python3.8/site-packages/flask/templating.py", line 89, in _get_source_fast
    raise TemplateNotFound(template)
jinja2.exceptions.TemplateNotFound: email/app/templates/reset_password.html
2021-04-04 22:35:52,977 INFO:         Microblog starting up [in /Users/inwaves/inwaves-repository/microblog/app/__init__.py:58]
2021-04-04 22:36:12,397 ERROR:         Exception on /reset_password/eyJ0eXAiOiJKV1QiLCJhbGciOiJIUzI1NiJ9.eyJyZXNldF9wYXNzd29yZCI6NCwiZXhwIjoxNjE3NTY1NTYwLjA1MjA5MTh9._P3KQVqrbnyiNTEHInENqW92QTjgtkO2NNZCtzBQ7fo [GET] [in /Users/inwaves/anaconda3/envs/todo-backend/lib/python3.8/site-packages/flask/app.py:1891]
Traceback (most recent call last):
  File "/Users/inwaves/anaconda3/envs/todo-backend/lib/python3.8/site-packages/flask/app.py", line 2447, in wsgi_app
    response = self.full_dispatch_request()
  File "/Users/inwaves/anaconda3/envs/todo-backend/lib/python3.8/site-packages/flask/app.py", line 1952, in full_dispatch_request
    rv = self.handle_user_exception(e)
  File "/Users/inwaves/anaconda3/envs/todo-backend/lib/python3.8/site-packages/flask/app.py", line 1821, in handle_user_exception
    reraise(exc_type, exc_value, tb)
  File "/Users/inwaves/anaconda3/envs/todo-backend/lib/python3.8/site-packages/flask/_compat.py", line 39, in reraise
    raise value
  File "/Users/inwaves/anaconda3/envs/todo-backend/lib/python3.8/site-packages/flask/app.py", line 1950, in full_dispatch_request
    rv = self.dispatch_request()
  File "/Users/inwaves/anaconda3/envs/todo-backend/lib/python3.8/site-packages/flask/app.py", line 1936, in dispatch_request
    return self.view_functions[rule.endpoint](**req.view_args)
  File "/Users/inwaves/inwaves-repository/microblog/app/routes.py", line 230, in reset_password
    return render_template("email/reset_password.html", form=form)
  File "/Users/inwaves/anaconda3/envs/todo-backend/lib/python3.8/site-packages/flask/templating.py", line 137, in render_template
    return _render(
  File "/Users/inwaves/anaconda3/envs/todo-backend/lib/python3.8/site-packages/flask/templating.py", line 120, in _render
    rv = template.render(context)
  File "/Users/inwaves/anaconda3/envs/todo-backend/lib/python3.8/site-packages/jinja2/environment.py", line 1090, in render
    self.environment.handle_exception()
  File "/Users/inwaves/anaconda3/envs/todo-backend/lib/python3.8/site-packages/jinja2/environment.py", line 832, in handle_exception
    reraise(*rewrite_traceback_stack(source=source))
  File "/Users/inwaves/anaconda3/envs/todo-backend/lib/python3.8/site-packages/jinja2/_compat.py", line 28, in reraise
    raise value.with_traceback(tb)
  File "/Users/inwaves/inwaves-repository/microblog/app/templates/email/reset_password.html", line 1, in top-level template code
    <p>Dear {{ user.username }},</p>
  File "/Users/inwaves/anaconda3/envs/todo-backend/lib/python3.8/site-packages/jinja2/environment.py", line 471, in getattr
    return getattr(obj, attribute)
jinja2.exceptions.UndefinedError: 'user' is undefined
2021-04-04 22:38:24,830 INFO:         Microblog starting up [in /Users/inwaves/inwaves-repository/microblog/app/__init__.py:58]
