2021-04-04 15:15:06,387 ERROR:         Exception on /user/Andrei1 [GET] [in /Users/inwaves/anaconda3/envs/todo-backend/lib/python3.8/site-packages/flask/app.py:1891]
Traceback (most recent call last):
  File "/Users/inwaves/anaconda3/envs/todo-backend/lib/python3.8/site-packages/flask/app.py", line 2447, in wsgi_app
    response = self.full_dispatch_request()
  File "/Users/inwaves/anaconda3/envs/todo-backend/lib/python3.8/site-packages/flask/app.py", line 1952, in full_dispatch_request
    rv = self.handle_user_exception(e)
  File "/Users/inwaves/anaconda3/envs/todo-backend/lib/python3.8/site-packages/flask/app.py", line 1821, in handle_user_exception
    reraise(exc_type, exc_value, tb)
  File "/Users/inwaves/anaconda3/envs/todo-backend/lib/python3.8/site-packages/flask/_compat.py", line 39, in reraise
    raise value
  File "/Users/inwaves/anaconda3/envs/todo-backend/lib/python3.8/site-packages/flask/app.py", line 1950, in full_dispatch_request
    rv = self.dispatch_request()
  File "/Users/inwaves/anaconda3/envs/todo-backend/lib/python3.8/site-packages/flask/app.py", line 1936, in dispatch_request
    return self.view_functions[rule.endpoint](**req.view_args)
  File "/Users/inwaves/anaconda3/envs/todo-backend/lib/python3.8/site-packages/flask_login/utils.py", line 272, in decorated_view
    return func(*args, **kwargs)
  File "/Users/inwaves/inwaves-repository/microblog/app/routes.py", line 101, in user
    return render_template("user.html", user=user, tasks=tasks, form=form)
  File "/Users/inwaves/anaconda3/envs/todo-backend/lib/python3.8/site-packages/flask/templating.py", line 138, in render_template
    ctx.app.jinja_env.get_or_select_template(template_name_or_list),
  File "/Users/inwaves/anaconda3/envs/todo-backend/lib/python3.8/site-packages/jinja2/environment.py", line 930, in get_or_select_template
    return self.get_template(template_name_or_list, parent, globals)
  File "/Users/inwaves/anaconda3/envs/todo-backend/lib/python3.8/site-packages/jinja2/environment.py", line 883, in get_template
    return self._load_template(name, self.make_globals(globals))
  File "/Users/inwaves/anaconda3/envs/todo-backend/lib/python3.8/site-packages/jinja2/environment.py", line 857, in _load_template
    template = self.loader.load(self, name, globals)
  File "/Users/inwaves/anaconda3/envs/todo-backend/lib/python3.8/site-packages/jinja2/loaders.py", line 127, in load
    code = environment.compile(source, name, filename)
  File "/Users/inwaves/anaconda3/envs/todo-backend/lib/python3.8/site-packages/jinja2/environment.py", line 638, in compile
    self.handle_exception(source=source_hint)
  File "/Users/inwaves/anaconda3/envs/todo-backend/lib/python3.8/site-packages/jinja2/environment.py", line 832, in handle_exception
    reraise(*rewrite_traceback_stack(source=source))
  File "/Users/inwaves/anaconda3/envs/todo-backend/lib/python3.8/site-packages/jinja2/_compat.py", line 28, in reraise
    raise value.with_traceback(tb)
  File "/Users/inwaves/inwaves-repository/microblog/app/templates/user.html", line 24, in template
    <form action="{{ url_for('follow', username=user.username }}" method="post">
jinja2.exceptions.TemplateSyntaxError: unexpected '}', expected ')'
2021-04-04 15:15:48,741 INFO:         Microblog starting up [in /Users/inwaves/inwaves-repository/microblog/app/__init__.py:56]
2021-04-04 15:17:33,915 INFO:         Microblog starting up [in /Users/inwaves/inwaves-repository/microblog/app/__init__.py:56]
2021-04-04 15:18:10,742 INFO:         Microblog starting up [in /Users/inwaves/inwaves-repository/microblog/app/__init__.py:56]
2021-04-04 15:18:39,853 INFO:         Microblog starting up [in /Users/inwaves/inwaves-repository/microblog/app/__init__.py:56]
2021-04-04 15:19:27,627 INFO:         Microblog starting up [in /Users/inwaves/inwaves-repository/microblog/app/__init__.py:56]
2021-04-04 16:31:12,482 INFO:         Microblog starting up [in /Users/inwaves/inwaves-repository/microblog/app/__init__.py:56]
2021-04-04 16:31:18,753 ERROR:         Exception on / [GET] [in /Users/inwaves/anaconda3/envs/todo-backend/lib/python3.8/site-packages/flask/app.py:1891]
Traceback (most recent call last):
  File "/Users/inwaves/anaconda3/envs/todo-backend/lib/python3.8/site-packages/flask/app.py", line 2447, in wsgi_app
    response = self.full_dispatch_request()
  File "/Users/inwaves/anaconda3/envs/todo-backend/lib/python3.8/site-packages/flask/app.py", line 1952, in full_dispatch_request
    rv = self.handle_user_exception(e)
  File "/Users/inwaves/anaconda3/envs/todo-backend/lib/python3.8/site-packages/flask/app.py", line 1821, in handle_user_exception
    reraise(exc_type, exc_value, tb)
  File "/Users/inwaves/anaconda3/envs/todo-backend/lib/python3.8/site-packages/flask/_compat.py", line 39, in reraise
    raise value
  File "/Users/inwaves/anaconda3/envs/todo-backend/lib/python3.8/site-packages/flask/app.py", line 1950, in full_dispatch_request
    rv = self.dispatch_request()
  File "/Users/inwaves/anaconda3/envs/todo-backend/lib/python3.8/site-packages/flask/app.py", line 1936, in dispatch_request
    return self.view_functions[rule.endpoint](**req.view_args)
  File "/Users/inwaves/anaconda3/envs/todo-backend/lib/python3.8/site-packages/flask_login/utils.py", line 272, in decorated_view
    return func(*args, **kwargs)
  File "/Users/inwaves/inwaves-repository/microblog/app/routes.py", line 34, in index
    per_page=app.config["POSTS_PER_PAGE"]
KeyError: 'POSTS_PER_PAGE'
2021-04-04 16:32:00,032 INFO:         Microblog starting up [in /Users/inwaves/inwaves-repository/microblog/app/__init__.py:56]
2021-04-04 16:32:02,475 ERROR:         Exception on / [GET] [in /Users/inwaves/anaconda3/envs/todo-backend/lib/python3.8/site-packages/flask/app.py:1891]
Traceback (most recent call last):
  File "/Users/inwaves/anaconda3/envs/todo-backend/lib/python3.8/site-packages/flask/app.py", line 2447, in wsgi_app
    response = self.full_dispatch_request()
  File "/Users/inwaves/anaconda3/envs/todo-backend/lib/python3.8/site-packages/flask/app.py", line 1952, in full_dispatch_request
    rv = self.handle_user_exception(e)
  File "/Users/inwaves/anaconda3/envs/todo-backend/lib/python3.8/site-packages/flask/app.py", line 1821, in handle_user_exception
    reraise(exc_type, exc_value, tb)
  File "/Users/inwaves/anaconda3/envs/todo-backend/lib/python3.8/site-packages/flask/_compat.py", line 39, in reraise
    raise value
  File "/Users/inwaves/anaconda3/envs/todo-backend/lib/python3.8/site-packages/flask/app.py", line 1950, in full_dispatch_request
    rv = self.dispatch_request()
  File "/Users/inwaves/anaconda3/envs/todo-backend/lib/python3.8/site-packages/flask/app.py", line 1936, in dispatch_request
    return self.view_functions[rule.endpoint](**req.view_args)
  File "/Users/inwaves/anaconda3/envs/todo-backend/lib/python3.8/site-packages/flask_login/utils.py", line 272, in decorated_view
    return func(*args, **kwargs)
  File "/Users/inwaves/inwaves-repository/microblog/app/routes.py", line 37, in index
    return render_template("index.html", title="Home Page", form=form, tasks=tasks)
  File "/Users/inwaves/anaconda3/envs/todo-backend/lib/python3.8/site-packages/flask/templating.py", line 137, in render_template
    return _render(
  File "/Users/inwaves/anaconda3/envs/todo-backend/lib/python3.8/site-packages/flask/templating.py", line 120, in _render
    rv = template.render(context)
  File "/Users/inwaves/anaconda3/envs/todo-backend/lib/python3.8/site-packages/jinja2/environment.py", line 1090, in render
    self.environment.handle_exception()
  File "/Users/inwaves/anaconda3/envs/todo-backend/lib/python3.8/site-packages/jinja2/environment.py", line 832, in handle_exception
    reraise(*rewrite_traceback_stack(source=source))
  File "/Users/inwaves/anaconda3/envs/todo-backend/lib/python3.8/site-packages/jinja2/_compat.py", line 28, in reraise
    raise value.with_traceback(tb)
  File "/Users/inwaves/inwaves-repository/microblog/app/templates/index.html", line 1, in top-level template code
    {% extends "base.html" %}
  File "/Users/inwaves/inwaves-repository/microblog/app/templates/base.html", line 43, in top-level template code
    {% block content %}{% endblock %}
  File "/Users/inwaves/inwaves-repository/microblog/app/templates/index.html", line 5, in block "content"
    {% for task in tasks %}
TypeError: 'Pagination' object is not iterable
2021-04-04 16:35:21,930 INFO:         Microblog starting up [in /Users/inwaves/inwaves-repository/microblog/app/__init__.py:56]
2021-04-04 16:35:25,086 INFO:         Microblog starting up [in /Users/inwaves/inwaves-repository/microblog/app/__init__.py:56]
2021-04-04 16:45:58,054 INFO:         Microblog starting up [in /Users/inwaves/inwaves-repository/microblog/app/__init__.py:56]
2021-04-04 16:46:42,627 INFO:         Microblog starting up [in /Users/inwaves/inwaves-repository/microblog/app/__init__.py:56]
2021-04-04 17:31:28,322 INFO:         Microblog starting up [in /Users/inwaves/inwaves-repository/microblog/app/__init__.py:58]
2021-04-04 17:33:43,745 INFO:         Microblog starting up [in /Users/inwaves/inwaves-repository/microblog/app/__init__.py:58]
