2021-04-06 00:05:33,247 ERROR: Exception on /index [POST] [in /Users/inwaves/anaconda3/envs/todo-backend/lib/python3.9/site-packages/flask/app.py:1891]
Traceback (most recent call last):
  File "/Users/inwaves/anaconda3/envs/todo-backend/lib/python3.9/site-packages/urllib3/connection.py", line 169, in _new_conn
    conn = connection.create_connection(
  File "/Users/inwaves/anaconda3/envs/todo-backend/lib/python3.9/site-packages/urllib3/util/connection.py", line 96, in create_connection
    raise err
  File "/Users/inwaves/anaconda3/envs/todo-backend/lib/python3.9/site-packages/urllib3/util/connection.py", line 86, in create_connection
    sock.connect(sa)
ConnectionRefusedError: [Errno 61] Connection refused

During handling of the above exception, another exception occurred:

Traceback (most recent call last):
  File "/Users/inwaves/anaconda3/envs/todo-backend/lib/python3.9/site-packages/elasticsearch/connection/http_urllib3.py", line 245, in perform_request
    response = self.pool.urlopen(
  File "/Users/inwaves/anaconda3/envs/todo-backend/lib/python3.9/site-packages/urllib3/connectionpool.py", line 755, in urlopen
    retries = retries.increment(
  File "/Users/inwaves/anaconda3/envs/todo-backend/lib/python3.9/site-packages/urllib3/util/retry.py", line 506, in increment
    raise six.reraise(type(error), error, _stacktrace)
  File "/Users/inwaves/anaconda3/envs/todo-backend/lib/python3.9/site-packages/urllib3/packages/six.py", line 735, in reraise
    raise value
  File "/Users/inwaves/anaconda3/envs/todo-backend/lib/python3.9/site-packages/urllib3/connectionpool.py", line 699, in urlopen
    httplib_response = self._make_request(
  File "/Users/inwaves/anaconda3/envs/todo-backend/lib/python3.9/site-packages/urllib3/connectionpool.py", line 394, in _make_request
    conn.request(method, url, **httplib_request_kw)
  File "/Users/inwaves/anaconda3/envs/todo-backend/lib/python3.9/site-packages/urllib3/connection.py", line 234, in request
    super(HTTPConnection, self).request(method, url, body=body, headers=headers)
  File "/Users/inwaves/anaconda3/envs/todo-backend/lib/python3.9/http/client.py", line 1255, in request
    self._send_request(method, url, body, headers, encode_chunked)
  File "/Users/inwaves/anaconda3/envs/todo-backend/lib/python3.9/http/client.py", line 1301, in _send_request
    self.endheaders(body, encode_chunked=encode_chunked)
  File "/Users/inwaves/anaconda3/envs/todo-backend/lib/python3.9/http/client.py", line 1250, in endheaders
    self._send_output(message_body, encode_chunked=encode_chunked)
  File "/Users/inwaves/anaconda3/envs/todo-backend/lib/python3.9/http/client.py", line 1010, in _send_output
    self.send(msg)
  File "/Users/inwaves/anaconda3/envs/todo-backend/lib/python3.9/http/client.py", line 950, in send
    self.connect()
  File "/Users/inwaves/anaconda3/envs/todo-backend/lib/python3.9/site-packages/urllib3/connection.py", line 200, in connect
    conn = self._new_conn()
  File "/Users/inwaves/anaconda3/envs/todo-backend/lib/python3.9/site-packages/urllib3/connection.py", line 181, in _new_conn
    raise NewConnectionError(
urllib3.exceptions.NewConnectionError: <urllib3.connection.HTTPConnection object at 0x7fe0182fd5b0>: Failed to establish a new connection: [Errno 61] Connection refused

During handling of the above exception, another exception occurred:

Traceback (most recent call last):
  File "/Users/inwaves/anaconda3/envs/todo-backend/lib/python3.9/site-packages/flask/app.py", line 2447, in wsgi_app
    response = self.full_dispatch_request()
  File "/Users/inwaves/anaconda3/envs/todo-backend/lib/python3.9/site-packages/flask/app.py", line 1952, in full_dispatch_request
    rv = self.handle_user_exception(e)
  File "/Users/inwaves/anaconda3/envs/todo-backend/lib/python3.9/site-packages/flask/app.py", line 1821, in handle_user_exception
    reraise(exc_type, exc_value, tb)
  File "/Users/inwaves/anaconda3/envs/todo-backend/lib/python3.9/site-packages/flask/_compat.py", line 39, in reraise
    raise value
  File "/Users/inwaves/anaconda3/envs/todo-backend/lib/python3.9/site-packages/flask/app.py", line 1950, in full_dispatch_request
    rv = self.dispatch_request()
  File "/Users/inwaves/anaconda3/envs/todo-backend/lib/python3.9/site-packages/flask/app.py", line 1936, in dispatch_request
    return self.view_functions[rule.endpoint](**req.view_args)
  File "/Users/inwaves/anaconda3/envs/todo-backend/lib/python3.9/site-packages/flask_login/utils.py", line 272, in decorated_view
    return func(*args, **kwargs)
  File "/Users/inwaves/inwaves-repository/o.microtasks/app/main/routes.py", line 35, in index
    db.session.commit()
  File "/Users/inwaves/anaconda3/envs/todo-backend/lib/python3.9/site-packages/sqlalchemy/orm/scoping.py", line 163, in do
    return getattr(self.registry(), name)(*args, **kwargs)
  File "/Users/inwaves/anaconda3/envs/todo-backend/lib/python3.9/site-packages/sqlalchemy/orm/session.py", line 1046, in commit
    self.transaction.commit()
  File "/Users/inwaves/anaconda3/envs/todo-backend/lib/python3.9/site-packages/sqlalchemy/orm/session.py", line 511, in commit
    self.session.dispatch.after_commit(self.session)
  File "/Users/inwaves/anaconda3/envs/todo-backend/lib/python3.9/site-packages/sqlalchemy/event/attr.py", line 261, in __call__
    fn(*args, **kw)
  File "/Users/inwaves/inwaves-repository/o.microtasks/app/models.py", line 38, in after_commit
    add_to_index(obj.__tablename__, obj)
  File "/Users/inwaves/inwaves-repository/o.microtasks/app/search.py", line 10, in add_to_index
    current_app.elasticsearch.index(index=index, id=model.id, body=payload)
  File "/Users/inwaves/anaconda3/envs/todo-backend/lib/python3.9/site-packages/elasticsearch/client/utils.py", line 152, in _wrapped
    return func(*args, params=params, headers=headers, **kwargs)
  File "/Users/inwaves/anaconda3/envs/todo-backend/lib/python3.9/site-packages/elasticsearch/client/__init__.py", line 398, in index
    return self.transport.perform_request(
  File "/Users/inwaves/anaconda3/envs/todo-backend/lib/python3.9/site-packages/elasticsearch/transport.py", line 390, in perform_request
    raise e
  File "/Users/inwaves/anaconda3/envs/todo-backend/lib/python3.9/site-packages/elasticsearch/transport.py", line 358, in perform_request
    status, headers_response, data = connection.perform_request(
  File "/Users/inwaves/anaconda3/envs/todo-backend/lib/python3.9/site-packages/elasticsearch/connection/http_urllib3.py", line 258, in perform_request
    raise ConnectionError("N/A", str(e), e)
elasticsearch.exceptions.ConnectionError: ConnectionError(<urllib3.connection.HTTPConnection object at 0x7fe0182fd5b0>: Failed to establish a new connection: [Errno 61] Connection refused) caused by: NewConnectionError(<urllib3.connection.HTTPConnection object at 0x7fe0182fd5b0>: Failed to establish a new connection: [Errno 61] Connection refused)
2021-04-06 00:07:23,949 INFO: Microblog startup [in /Users/inwaves/inwaves-repository/o.microtasks/app/__init__.py:85]
