2021-04-07 22:48:21,198 ERROR: Exception on /user/Andrei/popup [GET] [in /Users/inwaves/anaconda3/envs/todo-backend/lib/python3.9/site-packages/flask/app.py:1891]
Traceback (most recent call last):
  File "/Users/inwaves/anaconda3/envs/todo-backend/lib/python3.9/site-packages/flask/app.py", line 2447, in wsgi_app
    response = self.full_dispatch_request()
  File "/Users/inwaves/anaconda3/envs/todo-backend/lib/python3.9/site-packages/flask/app.py", line 1952, in full_dispatch_request
    rv = self.handle_user_exception(e)
  File "/Users/inwaves/anaconda3/envs/todo-backend/lib/python3.9/site-packages/flask/app.py", line 1821, in handle_user_exception
    reraise(exc_type, exc_value, tb)
  File "/Users/inwaves/anaconda3/envs/todo-backend/lib/python3.9/site-packages/flask/_compat.py", line 39, in reraise
    raise value
  File "/Users/inwaves/anaconda3/envs/todo-backend/lib/python3.9/site-packages/flask/app.py", line 1950, in full_dispatch_request
    rv = self.dispatch_request()
  File "/Users/inwaves/anaconda3/envs/todo-backend/lib/python3.9/site-packages/flask/app.py", line 1936, in dispatch_request
    return self.view_functions[rule.endpoint](**req.view_args)
  File "/Users/inwaves/anaconda3/envs/todo-backend/lib/python3.9/site-packages/flask_login/utils.py", line 272, in decorated_view
    return func(*args, **kwargs)
  File "/Users/inwaves/inwaves-repository/o.microtasks/app/main/routes.py", line 86, in user_popup
    return render_template("user_popup.html", user=user, form=form)
  File "/Users/inwaves/anaconda3/envs/todo-backend/lib/python3.9/site-packages/flask/templating.py", line 138, in render_template
    ctx.app.jinja_env.get_or_select_template(template_name_or_list),
  File "/Users/inwaves/anaconda3/envs/todo-backend/lib/python3.9/site-packages/jinja2/environment.py", line 930, in get_or_select_template
    return self.get_template(template_name_or_list, parent, globals)
  File "/Users/inwaves/anaconda3/envs/todo-backend/lib/python3.9/site-packages/jinja2/environment.py", line 883, in get_template
    return self._load_template(name, self.make_globals(globals))
  File "/Users/inwaves/anaconda3/envs/todo-backend/lib/python3.9/site-packages/jinja2/environment.py", line 857, in _load_template
    template = self.loader.load(self, name, globals)
  File "/Users/inwaves/anaconda3/envs/todo-backend/lib/python3.9/site-packages/jinja2/loaders.py", line 127, in load
    code = environment.compile(source, name, filename)
  File "/Users/inwaves/anaconda3/envs/todo-backend/lib/python3.9/site-packages/jinja2/environment.py", line 638, in compile
    self.handle_exception(source=source_hint)
  File "/Users/inwaves/anaconda3/envs/todo-backend/lib/python3.9/site-packages/jinja2/environment.py", line 832, in handle_exception
    reraise(*rewrite_traceback_stack(source=source))
  File "/Users/inwaves/anaconda3/envs/todo-backend/lib/python3.9/site-packages/jinja2/_compat.py", line 28, in reraise
    raise value.with_traceback(tb)
  File "/Users/inwaves/inwaves-repository/o.microtasks/app/templates/user_popup.html", line 13, in template
    {{ _('%(count)d following', count=user.followed.count()) }
jinja2.exceptions.TemplateSyntaxError: unexpected '}'
2021-04-07 22:49:38,087 INFO: Microblog startup [in /Users/inwaves/inwaves-repository/o.microtasks/app/__init__.py:87]
2021-04-07 22:59:32,984 INFO: Microblog startup [in /Users/inwaves/inwaves-repository/o.microtasks/app/__init__.py:87]
2021-04-07 22:59:35,609 INFO: Microblog startup [in /Users/inwaves/inwaves-repository/o.microtasks/app/__init__.py:87]
2021-04-08 10:23:49,271 INFO: Microblog startup [in /Users/inwaves/inwaves-repository/o.microtasks/app/__init__.py:87]
2021-04-08 10:45:17,210 INFO: Microblog startup [in /Users/inwaves/inwaves-repository/o.microtasks/app/__init__.py:87]
2021-04-08 10:45:27,130 INFO: Microblog startup [in /Users/inwaves/inwaves-repository/o.microtasks/app/__init__.py:87]
